File: Data/Tensile/Tensile/T11.txt
""
"Test Method","MTS EM Tension.msm"
"Sample I. D.","DIC.mss"
"Specimen Number","3"

"Load (N)","Time (s)","Extension (mm)","Stress (MPa)","Strain (mm/mm)"

40.953,2.000,-0.133,13.743,-0.003
67.803,3.000,-0.130,22.754,-0.003
102.618,4.000,-0.127,34.437,-0.002
140.014,5.000,-0.123,46.986,-0.002
167.304,6.000,-0.120,56.144,-0.002
190.647,7.000,-0.117,63.978,-0.002
200.647,8.000,-0.113,67.333,-0.002
202.472,9.000,-0.110,67.946,-0.002
204.150,10.000,-0.107,68.509,-0.002
208.381,11.000,-0.104,69.929,-0.002
209.997,12.000,-0.099,70.471,-0.002
210.096,13.000,-0.097,70.504,-0.002
212.267,14.000,-0.094,71.233,-0.002
215.819,15.000,-0.090,72.425,-0.002
216.707,16.000,-0.086,72.723,-0.002
217.990,17.000,-0.083,73.154,-0.002
219.396,18.000,-0.080,73.625,-0.002
221.728,19.000,-0.076,74.408,-0.002
221.814,20.000,-0.073,74.437,-0.001
223.035,21.000,-0.070,74.847,-0.001
224.799,22.000,-0.067,75.439,-0.001
225.034,23.000,-0.063,75.517,-0.001
225.539,24.000,-0.060,75.687,-0.001
225.527,25.000,-0.057,75.683,-0.001
226.058,26.000,-0.054,75.861,-0.001
223.973,27.000,-0.050,75.161,-0.001
224.158,28.000,-0.047,75.223,-0.001
224.355,29.000,-0.044,75.290,-0.001
225.786,30.000,-0.040,75.770,-0.001
223.936,31.000,-0.037,75.149,-0.001
223.319,32.000,-0.034,74.942,-0.001
225.243,33.000,-0.030,75.588,-0.001
226.206,34.000,-0.026,75.910,-0.001
226.132,35.000,-0.023,75.886,-0.000
227.575,36.000,-0.020,76.370,-0.000
229.043,37.000,-0.016,76.863,-0.000
231.164,38.000,-0.013,77.575,-0.000
235.062,39.000,-0.010,78.883,-0.000
245.930,40.000,-0.007,82.530,-0.000
259.881,41.000,-0.003,87.211,-0.000
268.072,42.000,0.000,89.960,0.000
275.115,43.000,0.003,92.324,0.000
284.058,44.000,0.006,95.325,0.000
292.940,45.000,0.010,98.305,0.000
298.232,46.000,0.013,100.081,0.000
305.251,47.000,0.016,102.436,0.000
314.009,48.000,0.020,105.376,0.000
320.349,49.000,0.024,107.503,0.000
327.454,50.000,0.026,109.888,0.001
335.521,51.000,0.029,112.595,0.001
343.194,52.000,0.034,115.170,0.001
347.696,53.000,0.037,116.681,0.001
353.408,54.000,0.040,118.597,0.001
360.044,55.000,0.043,120.824,0.001
367.495,56.000,0.047,123.324,0.001
371.664,57.000,0.050,124.724,0.001
377.092,58.000,0.053,126.545,0.001
385.850,59.000,0.057,129.484,0.001
390.290,60.000,0.060,130.974,0.001
396.606,61.000,0.063,133.094,0.001
401.318,62.000,0.066,134.675,0.001
411.828,63.000,0.070,138.202,0.001
414.961,64.000,0.073,139.253,0.001
422.510,65.000,0.076,141.787,0.002
428.530,66.000,0.080,143.807,0.002
436.289,67.000,0.084,146.411,0.002
441.667,68.000,0.086,148.215,0.002
445.479,69.000,0.089,149.495,0.002
453.842,70.000,0.093,152.301,0.002
458.838,71.000,0.097,153.978,0.002
464.636,72.000,0.100,155.923,0.002
469.360,73.000,0.103,157.509,0.002
480.388,74.000,0.107,161.209,0.002
490.564,75.000,0.110,164.624,0.002
499.754,76.000,0.113,167.708,0.002
512.805,77.000,0.117,172.088,0.002
523.981,78.000,0.121,175.838,0.002
534.071,79.000,0.123,179.225,0.002
543.323,80.000,0.126,182.329,0.002
554.671,81.000,0.130,186.138,0.003
563.158,82.000,0.134,188.986,0.003
572.212,83.000,0.137,192.024,0.003
579.983,84.000,0.140,194.632,0.003
592.417,85.000,0.144,198.804,0.003
600.213,86.000,0.147,201.421,0.003
607.010,87.000,0.150,203.702,0.003
619.160,88.000,0.153,207.779,0.003
628.893,89.000,0.157,211.045,0.003
636.430,90.000,0.160,213.574,0.003
643.831,91.000,0.163,216.058,0.003
656.240,92.000,0.167,220.222,0.003
664.349,93.000,0.170,222.943,0.003
672.745,94.000,0.173,225.761,0.003
683.107,95.000,0.176,229.238,0.003
695.171,96.000,0.180,233.287,0.004
702.473,97.000,0.183,235.737,0.004
712.416,98.000,0.186,239.074,0.004
724.060,99.000,0.190,242.981,0.004
734.595,100.000,0.194,246.517,0.004
742.144,101.000,0.197,249.050,0.004
752.913,102.000,0.200,252.664,0.004
765.902,103.000,0.204,257.023,0.004
773.204,104.000,0.207,259.473,0.004
781.691,105.000,0.210,262.321,0.004
793.163,106.000,0.213,266.171,0.004
807.410,107.000,0.217,270.952,0.004
814.195,108.000,0.220,273.229,0.004
824.297,109.000,0.223,276.619,0.004
837.792,110.000,0.226,281.148,0.004
848.376,111.000,0.230,284.699,0.005
857.578,112.000,0.233,287.788,0.005
866.361,113.000,0.236,290.735,0.005
883.162,114.000,0.240,296.373,0.005
891.105,115.000,0.243,299.039,0.005
901.443,116.000,0.246,302.508,0.005
912.865,117.000,0.249,306.341,0.005
926.459,118.000,0.254,310.903,0.005
933.070,119.000,0.257,313.121,0.005
942.852,120.000,0.260,316.404,0.005
958.308,121.000,0.263,321.591,0.005
967.992,122.000,0.267,324.840,0.005
977.132,123.000,0.270,327.908,0.005
987.765,124.000,0.273,331.476,0.005
1003.727,125.000,0.277,336.833,0.005
1011.054,126.000,0.280,339.291,0.006
1021.120,127.000,0.283,342.669,0.006
1032.062,128.000,0.286,346.341,0.006
1048.332,129.000,0.290,351.801,0.006
1055.092,130.000,0.293,354.069,0.006
1065.182,131.000,0.296,357.456,0.006
1079.762,132.000,0.300,362.349,0.006
1090.173,133.000,0.303,365.842,0.006
1097.636,134.000,0.306,368.347,0.006
1108.060,135.000,0.309,371.845,0.006
1124.244,136.000,0.313,377.276,0.006
1130.855,137.000,0.317,379.494,0.006
1139.798,138.000,0.320,382.496,0.006
1151.603,139.000,0.323,386.457,0.006
1164.555,140.000,0.327,390.804,0.006
1170.316,141.000,0.330,392.737,0.006
1179.161,142.000,0.333,395.705,0.007
1193.013,143.000,0.337,400.353,0.007
1200.772,144.000,0.340,402.957,0.007
1209.382,145.000,0.343,405.847,0.007
1216.463,146.000,0.346,408.223,0.007
1233.313,147.000,0.350,413.877,0.007
1237.359,148.000,0.353,415.235,0.007
1246.363,149.000,0.356,418.257,0.007
1257.724,150.000,0.360,422.069,0.007
1270.171,151.000,0.364,426.246,0.007
1274.562,152.000,0.367,427.720,0.007
1284.332,153.000,0.369,430.998,0.007
1298.961,154.000,0.373,435.908,0.007
1307.621,155.000,0.377,438.814,0.007
1313.320,156.000,0.380,440.726,0.007
1321.535,157.000,0.382,443.483,0.008
1338.583,158.000,0.387,449.204,0.008
1344.158,159.000,0.390,451.075,0.008
1353.311,160.000,0.393,454.146,0.008
1365.005,161.000,0.396,458.071,0.008
1377.019,162.000,0.400,462.103,0.008
1382.817,163.000,0.403,464.048,0.008
1391.686,164.000,0.406,467.024,0.008
1405.440,165.000,0.410,471.640,0.008
1413.322,166.000,0.414,474.285,0.008
1420.465,167.000,0.417,476.682,0.008
1430.111,168.000,0.419,479.919,0.008
1443.754,169.000,0.424,484.497,0.008
1448.663,170.000,0.427,486.145,0.008
1455.990,171.000,0.430,488.604,0.008
1467.068,172.000,0.433,492.321,0.009
1478.268,173.000,0.437,496.080,0.009
1484.164,174.000,0.440,498.058,0.009
1491.393,175.000,0.443,500.484,0.009
1505.258,176.000,0.446,505.137,0.009
1513.177,177.000,0.450,507.795,0.009
1519.591,178.000,0.453,509.947,0.009
1528.539,179.000,0.456,512.950,0.009
1543.325,180.000,0.460,517.912,0.009
1548.357,181.000,0.463,519.600,0.009
1555.857,182.000,0.466,522.117,0.009
1567.699,183.000,0.469,526.091,0.009
1579.961,184.000,0.474,530.206,0.009
1585.721,185.000,0.476,532.139,0.009
1592.049,186.000,0.479,534.263,0.009
1606.876,187.000,0.483,539.238,0.010
1613.143,188.000,0.487,541.341,0.010
1621.827,189.000,0.490,544.255,0.010
1631.152,190.000,0.493,547.385,0.010
1646.325,191.000,0.497,552.477,0.010
1650.840,192.000,0.500,553.992,0.010
1659.265,193.000,0.503,556.819,0.010
1669.639,194.000,0.506,560.300,0.010
1682.554,195.000,0.510,564.634,0.010
1688.758,196.000,0.513,566.716,0.010
1695.790,197.000,0.516,569.076,0.010
1712.418,198.000,0.520,574.656,0.010
1718.980,199.000,0.523,576.858,0.010
1726.455,200.000,0.526,579.367,0.010
1735.781,201.000,0.529,582.496,0.010
1749.202,202.000,0.533,587.000,0.010
1755.246,203.000,0.536,589.028,0.011
1763.782,204.000,0.539,591.893,0.011
1776.709,205.000,0.543,596.231,0.011
1790.402,206.000,0.547,600.826,0.011
1795.385,207.000,0.550,602.498,0.011
1804.020,208.000,0.553,605.396,0.011
1818.921,209.000,0.557,610.397,0.011
1825.841,210.000,0.560,612.719,0.011
1834.932,211.000,0.563,615.770,0.011
1845.269,212.000,0.566,619.239,0.011
1859.998,213.000,0.570,624.181,0.011
1865.450,214.000,0.573,626.011,0.011
1873.715,215.000,0.576,628.784,0.011
1887.135,216.000,0.580,633.288,0.011
1898.311,217.000,0.584,637.039,0.011
1905.022,218.000,0.586,639.290,0.012
1912.793,219.000,0.589,641.898,0.012
1927.053,220.000,0.593,646.684,0.012
1936.773,221.000,0.597,649.946,0.012
1943.755,222.000,0.599,652.289,0.012
1951.119,223.000,0.602,654.760,0.012
1968.894,224.000,0.607,660.725,0.012
1974.544,225.000,0.610,662.621,0.012
1984.289,226.000,0.613,665.891,0.012
1995.711,227.000,0.616,669.724,0.012
2010.020,228.000,0.620,674.526,0.012
2015.509,229.000,0.623,676.368,0.012
2025.119,230.000,0.626,679.593,0.012
2040.266,231.000,0.630,684.676,0.012
2048.654,232.000,0.633,687.491,0.012
2056.648,233.000,0.636,690.173,0.013
2068.083,234.000,0.639,694.011,0.013
2082.947,235.000,0.644,698.999,0.013
2089.336,236.000,0.647,701.143,0.013
2098.378,237.000,0.649,704.177,0.013
2112.576,238.000,0.653,708.942,0.013
2123.456,239.000,0.657,712.593,0.013
2130.253,240.000,0.660,714.874,0.013
2137.161,241.000,0.662,717.192,0.013
2155.405,242.000,0.666,723.314,0.013
2162.460,243.000,0.670,725.682,0.013
2169.714,244.000,0.673,728.116,0.013
2180.347,245.000,0.676,731.685,0.013
2197.345,246.000,0.680,737.389,0.013
2202.920,247.000,0.683,739.260,0.013
2211.937,248.000,0.686,742.286,0.014
2225.765,249.000,0.689,746.926,0.014
2241.357,250.000,0.693,752.159,0.014
2248.981,251.000,0.696,754.717,0.014
2257.665,252.000,0.699,757.631,0.014
2275.822,253.000,0.703,763.724,0.014
2284.161,254.000,0.707,766.523,0.014
2294.301,255.000,0.710,769.925,0.014
2305.156,256.000,0.713,773.568,0.014
2322.672,257.000,0.717,779.446,0.014
2329.136,258.000,0.720,781.615,0.014
2337.474,259.000,0.723,784.414,0.014
2352.153,260.000,0.726,789.340,0.014
2364.982,261.000,0.730,793.645,0.014
2371.421,262.000,0.733,795.806,0.014
2380.895,263.000,0.736,798.985,0.014
2399.225,264.000,0.740,805.136,0.015
2407.897,265.000,0.743,808.046,0.015
2415.927,266.000,0.746,810.741,0.015
2425.438,267.000,0.749,813.933,0.015
2443.090,268.000,0.753,819.856,0.015
2448.838,269.000,0.756,821.785,0.015
2457.633,270.000,0.759,824.737,0.015
2472.176,271.000,0.763,829.617,0.015
2485.227,272.000,0.767,833.997,0.015
2491.864,273.000,0.769,836.224,0.015
2500.178,274.000,0.772,839.014,0.015
2517.435,275.000,0.776,844.805,0.015
2525.625,276.000,0.780,847.554,0.015
2532.447,277.000,0.783,849.843,0.015
2542.044,278.000,0.786,853.063,0.015
2558.721,279.000,0.790,858.660,0.016
2562.644,280.000,0.793,859.976,0.016
2570.810,281.000,0.796,862.717,0.016
2585.958,282.000,0.800,867.800,0.016
2595.999,283.000,0.803,871.170,0.016
2601.068,284.000,0.806,872.871,0.016
2609.395,285.000,0.809,875.665,0.016
2626.208,286.000,0.813,881.307,0.016
2632.388,287.000,0.816,883.381,0.016
2639.912,288.000,0.819,885.906,0.016
2649.361,289.000,0.822,889.077,0.016
2667.025,290.000,0.826,895.005,0.016
2670.775,291.000,0.829,896.263,0.016
2679.558,292.000,0.832,899.211,0.016
2692.461,293.000,0.836,903.541,0.016
2703.698,294.000,0.840,907.312,0.017
2709.163,295.000,0.843,909.146,0.017
2717.822,296.000,0.846,912.052,0.017
2733.698,297.000,0.850,917.379,0.017
2740.100,298.000,0.853,919.528,0.017
2746.810,299.000,0.856,921.779,0.017
2757.246,300.000,0.859,925.281,0.017
2771.617,301.000,0.863,930.104,0.017
2776.008,302.000,0.866,931.578,0.017
2782.225,303.000,0.869,933.664,0.017
2795.683,304.000,0.873,938.180,0.017
2804.219,305.000,0.876,941.045,0.017
2809.474,306.000,0.879,942.808,0.017
2815.592,307.000,0.882,944.861,0.017
2831.135,308.000,0.886,950.077,0.017
2836.192,309.000,0.890,951.774,0.018
2842.360,310.000,0.892,953.844,0.018
2850.884,311.000,0.896,956.705,0.018
2864.514,312.000,0.900,961.279,0.018
2866.809,313.000,0.903,962.049,0.018
2873.618,314.000,0.906,964.334,0.018
2886.706,315.000,0.909,968.726,0.018
2893.798,316.000,0.913,971.106,0.018
2897.055,317.000,0.916,972.199,0.018
2904.247,318.000,0.919,974.612,0.018
2917.532,319.000,0.923,979.070,0.018
2919.777,320.000,0.926,979.824,0.018
2926.598,321.000,0.929,982.113,0.018
2934.530,322.000,0.933,984.775,0.018
2943.041,323.000,0.937,987.631,0.018
2945.360,324.000,0.940,988.409,0.018
2950.294,325.000,0.942,990.065,0.019
2959.830,326.000,0.946,993.265,0.019
2964.295,327.000,0.950,994.763,0.019
2967.737,328.000,0.953,995.918,0.019
2972.572,329.000,0.955,997.541,0.019
2983.106,330.000,0.960,1001.076,0.019
2985.154,331.000,0.963,1001.763,0.019
2988.596,332.000,0.966,1002.918,0.019
2995.195,333.000,0.969,1005.133,0.019
3002.621,334.000,0.973,1007.625,0.019
3004.076,335.000,0.976,1008.113,0.019
3006.938,336.000,0.979,1009.074,0.019
3016.239,337.000,0.983,1012.195,0.019
3018.015,338.000,0.986,1012.791,0.019
3020.334,339.000,0.989,1013.569,0.019
3023.492,340.000,0.992,1014.629,0.020
3031.387,341.000,0.997,1017.278,0.020
3031.387,342.000,1.000,1017.278,0.020
3032.818,343.000,1.003,1017.758,0.020
3040.860,344.000,1.006,1020.457,0.020
3044.561,345.000,1.010,1021.699,0.020
3042.834,346.000,1.013,1021.120,0.020
3045.992,347.000,1.016,1022.179,0.020
3054.207,348.000,1.020,1024.936,0.020
3054.158,349.000,1.023,1024.920,0.020
3056.477,350.000,1.026,1025.698,0.020
3059.462,351.000,1.029,1026.700,0.020
3065.507,352.000,1.033,1028.728,0.020
3064.150,353.000,1.036,1028.273,0.020
3066.025,354.000,1.039,1028.902,0.020
3070.786,355.000,1.042,1030.500,0.021
3074.659,356.000,1.046,1031.800,0.021
3072.242,357.000,1.049,1030.988,0.021
3076.337,358.000,1.052,1032.362,0.021
3082.110,359.000,1.056,1034.300,0.021
3082.258,360.000,1.060,1034.349,0.021
3084.207,361.000,1.063,1035.003,0.021
3086.329,362.000,1.066,1035.715,0.021
3093.138,363.000,1.070,1038.001,0.021
3091.731,364.000,1.073,1037.529,0.021
3093.594,365.000,1.076,1038.154,0.021
3099.527,366.000,1.079,1040.145,0.021
3099.133,367.000,1.083,1040.012,0.021
3099.873,368.000,1.086,1040.261,0.021
3100.958,369.000,1.089,1040.625,0.021
3107.718,370.000,1.093,1042.893,0.022
3105.646,371.000,1.096,1042.198,0.022
3108.434,372.000,1.099,1043.134,0.022
3110.284,373.000,1.102,1043.754,0.022
3117.833,374.000,1.106,1046.288,0.022
3113.565,375.000,1.109,1044.856,0.022
3115.983,376.000,1.112,1045.667,0.022
3121.090,377.000,1.116,1047.381,0.022
3122.866,378.000,1.120,1047.977,0.022
3121.090,379.000,1.123,1047.381,0.022
3122.718,380.000,1.126,1047.927,0.022
3129.206,381.000,1.130,1050.104,0.022
3126.554,382.000,1.133,1049.214,0.022
3126.591,383.000,1.136,1049.227,0.022
3130.761,384.000,1.139,1050.626,0.022
3135.226,385.000,1.143,1052.125,0.023
3133.277,386.000,1.146,1051.470,0.023
3135.201,387.000,1.149,1052.116,0.023
3141.468,388.000,1.153,1054.219,0.023
3141.369,389.000,1.157,1054.186,0.023
3140.135,390.000,1.159,1053.772,0.023
3141.024,391.000,1.162,1054.070,0.023
3147.623,392.000,1.166,1056.285,0.023
3145.674,393.000,1.170,1055.631,0.023
3146.698,394.000,1.173,1055.974,0.023
3149.782,395.000,1.176,1057.009,0.023
3153.384,396.000,1.180,1058.218,0.023
3150.867,397.000,1.183,1057.373,0.023
3151.990,398.000,1.185,1057.750,0.023
3157.109,399.000,1.189,1059.468,0.023
3157.948,400.000,1.193,1059.750,0.023
3157.059,401.000,1.196,1059.451,0.024
3157.812,402.000,1.199,1059.704,0.024
3163.536,403.000,1.203,1061.625,0.024
3160.834,404.000,1.206,1060.718,0.024
3162.956,405.000,1.209,1061.430,0.024
3166.508,406.000,1.212,1062.622,0.024
3169.493,407.000,1.217,1063.624,0.024
3166.434,408.000,1.220,1062.598,0.024
3169.197,409.000,1.223,1063.525,0.024
3173.539,410.000,1.226,1064.982,0.024
3173.095,411.000,1.230,1064.833,0.024
3172.380,412.000,1.233,1064.593,0.024
3173.811,413.000,1.236,1065.073,0.024
3179.362,414.000,1.240,1066.936,0.024
3175.637,415.000,1.243,1065.686,0.024
3176.500,416.000,1.246,1065.975,0.025
3180.373,417.000,1.249,1067.275,0.025
3184.012,418.000,1.253,1068.496,0.025
3179.510,419.000,1.256,1066.985,0.025
3182.396,420.000,1.259,1067.954,0.025
3188.564,421.000,1.262,1070.024,0.025
3187.935,422.000,1.266,1069.813,0.025
3186.245,423.000,1.269,1069.246,0.025
3188.009,424.000,1.272,1069.838,0.025
3193.769,425.000,1.276,1071.771,0.025
3189.810,426.000,1.279,1070.442,0.025
3191.327,427.000,1.282,1070.951,0.025
3195.250,428.000,1.286,1072.267,0.025
3197.211,429.000,1.290,1072.926,0.025
3195.644,430.000,1.293,1072.400,0.025
3196.335,431.000,1.296,1072.632,0.026
3201.590,432.000,1.300,1074.395,0.026
3199.715,433.000,1.303,1073.766,0.026
3200.184,434.000,1.306,1073.923,0.026
3200.665,435.000,1.309,1074.085,0.026
3206.549,436.000,1.313,1076.059,0.026
3201.738,437.000,1.316,1074.445,0.026
3203.366,438.000,1.319,1074.991,0.026
3207.363,439.000,1.322,1076.332,0.026
3210.151,440.000,1.326,1077.268,0.026
3206.055,441.000,1.329,1075.894,0.026
3208.498,442.000,1.332,1076.713,0.026
3215.196,443.000,1.336,1078.961,0.026
3212.667,444.000,1.340,1078.112,0.026
3212.495,445.000,1.343,1078.054,0.026
3213.999,446.000,1.345,1078.559,0.026
3219.328,447.000,1.350,1080.348,0.027
3215.603,448.000,1.353,1079.098,0.027
3216.602,449.000,1.356,1079.433,0.027
3220.118,450.000,1.359,1080.613,0.027
3221.586,451.000,1.363,1081.105,0.027
3218.810,452.000,1.366,1080.174,0.027
3219.254,453.000,1.369,1080.323,0.027
3225.397,454.000,1.373,1082.384,0.027
3223.720,455.000,1.376,1081.821,0.027
3223.695,456.000,1.379,1081.813,0.027
3224.410,457.000,1.382,1082.053,0.027
3231.121,458.000,1.386,1084.305,0.027
3226.606,459.000,1.390,1082.790,0.027
3227.445,460.000,1.392,1083.072,0.027
3230.998,461.000,1.396,1084.264,0.027
3232.182,462.000,1.400,1084.661,0.028
3229.702,463.000,1.403,1083.829,0.028
3230.430,464.000,1.405,1084.073,0.028
3235.956,465.000,1.409,1085.928,0.028
3233.440,466.000,1.413,1085.083,0.028
3234.007,467.000,1.416,1085.274,0.028
3234.994,468.000,1.419,1085.605,0.028
3240.767,469.000,1.423,1087.542,0.028
3236.413,470.000,1.426,1086.081,0.028
3237.252,471.000,1.429,1086.362,0.028
3242.173,472.000,1.432,1088.014,0.028
3242.963,473.000,1.437,1088.279,0.028
3241.483,474.000,1.439,1087.782,0.028
3241.507,475.000,1.442,1087.791,0.028
3246.639,476.000,1.446,1089.513,0.028
3243.358,477.000,1.450,1088.412,0.029
3244.936,478.000,1.453,1088.941,0.029
3247.416,479.000,1.456,1089.773,0.029
3250.783,480.000,1.460,1090.904,0.029
3246.614,481.000,1.463,1089.504,0.029
3247.305,482.000,1.466,1089.736,0.029
3251.499,483.000,1.469,1091.144,0.029
3252.757,484.000,1.473,1091.566,0.029
3249.402,485.000,1.476,1090.440,0.029
3250.068,486.000,1.479,1090.663,0.029
3257.753,487.000,1.483,1093.242,0.029
3253.053,488.000,1.486,1091.665,0.029
3253.917,489.000,1.489,1091.955,0.029
3255.570,490.000,1.492,1092.510,0.029
3259.295,491.000,1.496,1093.760,0.029
3256.186,492.000,1.499,1092.717,0.030
3258.456,493.000,1.502,1093.478,0.030
3262.206,494.000,1.506,1094.737,0.030
3260.430,495.000,1.510,1094.141,0.030
3260.627,496.000,1.513,1094.207,0.030
3260.664,497.000,1.516,1094.219,0.030
3266.523,498.000,1.520,1096.186,0.030
3262.527,499.000,1.523,1094.844,0.030
3263.674,500.000,1.526,1095.229,0.030
3266.203,501.000,1.529,1096.078,0.030
3269.360,502.000,1.533,1097.138,0.030
3264.870,503.000,1.536,1095.631,0.030
3266.573,504.000,1.539,1096.202,0.030
3271.803,505.000,1.542,1097.957,0.030
3270.397,506.000,1.546,1097.485,0.030
3269.410,507.000,1.549,1097.154,0.030
3270.841,508.000,1.552,1097.634,0.031
3275.911,509.000,1.556,1099.336,0.031
3271.556,510.000,1.559,1097.874,0.031
3273.789,511.000,1.562,1098.624,0.031
3274.714,512.000,1.565,1098.934,0.031
3279.426,513.000,1.570,1100.515,0.031
3274.726,514.000,1.573,1098.938,0.031
3275.331,515.000,1.576,1099.141,0.031
3279.673,516.000,1.579,1100.598,0.031
3279.488,517.000,1.583,1100.536,0.031
3277.971,518.000,1.586,1100.027,0.031
3279.192,519.000,1.589,1100.437,0.031
3284.286,520.000,1.593,1102.146,0.031
3280.080,521.000,1.596,1100.735,0.031
3280.758,522.000,1.599,1100.963,0.031
3282.905,523.000,1.602,1101.683,0.032
3286.334,524.000,1.607,1102.834,0.032
3282.732,525.000,1.609,1101.625,0.032
3284.817,526.000,1.612,1102.324,0.032
3289.812,527.000,1.616,1104.001,0.032
3288.419,528.000,1.620,1103.533,0.032
3286.827,529.000,1.623,1102.999,0.032
3287.962,530.000,1.625,1103.380,0.032
3294.229,531.000,1.629,1105.483,0.032
3289.270,532.000,1.633,1103.819,0.032
3290.454,533.000,1.636,1104.216,0.032
3292.156,534.000,1.639,1104.787,0.032
3295.684,535.000,1.643,1105.971,0.032
3292.514,536.000,1.646,1104.908,0.032
3292.835,537.000,1.649,1105.015,0.032
3298.003,538.000,1.653,1106.750,0.033
3295.191,539.000,1.656,1105.806,0.033
3293.612,540.000,1.659,1105.276,0.033
3294.969,541.000,1.662,1105.731,0.033
3301.038,542.000,1.666,1107.768,0.033
3297.238,543.000,1.670,1106.493,0.033
3297.978,544.000,1.673,1106.741,0.033
3300.446,545.000,1.676,1107.569,0.033
3303.085,546.000,1.680,1108.455,0.033
3299.594,547.000,1.683,1107.284,0.033
3300.495,548.000,1.686,1107.586,0.033
3305.725,549.000,1.689,1109.341,0.033
3303.825,550.000,1.693,1108.703,0.033
3302.715,551.000,1.696,1108.331,0.033
3303.283,552.000,1.699,1108.521,0.033
3308.710,553.000,1.703,1110.343,0.034
3303.751,554.000,1.706,1108.679,0.034
3305.355,555.000,1.709,1109.217,0.034
3307.427,556.000,1.712,1109.912,0.034
3311.128,557.000,1.717,1111.154,0.034
3306.317,558.000,1.719,1109.540,0.034
3306.811,559.000,1.722,1109.705,0.034
3312.880,560.000,1.726,1111.742,0.034
3310.363,561.000,1.730,1110.897,0.034
3309.931,562.000,1.733,1110.753,0.034
3309.722,563.000,1.736,1110.682,0.034
3314.360,564.000,1.740,1112.239,0.034
3308.809,565.000,1.743,1110.376,0.034
3310.474,566.000,1.746,1110.935,0.034
3312.510,567.000,1.749,1111.618,0.034
3315.211,568.000,1.753,1112.524,0.035
3310.351,569.000,1.756,1110.893,0.035
3308.315,570.000,1.759,1110.210,0.035
3299.163,571.000,1.762,1107.139,0.035
3284.656,572.000,1.766,1102.271,0.035
3267.782,573.000,1.769,1096.608,0.035
3265.413,574.000,1.772,1095.813,0.035
3244.677,575.000,1.776,1088.854,0.035
3231.812,576.000,1.779,1084.537,0.035
3227.827,577.000,1.782,1083.200,0.035
3217.478,578.000,1.785,1079.727,0.035
-12.237,578.810,1.789,-4.106,0.035