File: Data/Tensile/T7.txt
""
"Test Method","MTS EM Tension.msm"
"Sample I. D.","DIC.mss"
"Specimen Number","5"

"Load (N)","Time (s)","Extension (mm)","Stress (MPa)","Strain (mm/mm)"

61.307,2.000,0.035,20.783,0.001
96.709,3.000,0.038,32.785,0.001
129.904,4.000,0.041,44.038,0.001
167.008,5.000,0.044,56.617,0.001
212.143,6.000,0.049,71.918,0.001
240.564,7.000,0.052,81.553,0.001
265.333,8.000,0.054,89.950,0.001
298.429,9.000,0.058,101.169,0.001
324.198,10.000,0.062,109.905,0.001
343.034,11.000,0.065,116.290,0.001
361.290,12.000,0.068,122.479,0.001
386.762,13.000,0.072,131.115,0.001
399.246,14.000,0.075,135.347,0.001
412.716,15.000,0.078,139.913,0.002
426.359,16.000,0.081,144.538,0.002
442.494,17.000,0.085,150.008,0.002
450.610,18.000,0.088,152.760,0.002
460.627,19.000,0.091,156.155,0.002
477.057,20.000,0.095,161.725,0.002
488.245,21.000,0.098,165.518,0.002
497.065,22.000,0.101,168.508,0.002
507.254,23.000,0.104,171.962,0.002
522.316,24.000,0.108,177.068,0.002
531.098,25.000,0.111,180.046,0.002
540.276,26.000,0.114,183.157,0.002
552.007,27.000,0.118,187.134,0.002
564.095,28.000,0.122,191.232,0.002
572.113,29.000,0.125,193.950,0.002
582.475,30.000,0.128,197.463,0.003
595.797,31.000,0.132,201.979,0.003
604.383,32.000,0.135,204.889,0.003
614.325,33.000,0.138,208.260,0.003
624.477,34.000,0.141,211.701,0.003
637.935,35.000,0.145,216.264,0.003
644.769,36.000,0.148,218.580,0.003
654.884,37.000,0.151,222.009,0.003
668.502,38.000,0.155,226.626,0.003
679.024,39.000,0.159,230.193,0.003
686.277,40.000,0.161,232.652,0.003
694.973,41.000,0.164,235.600,0.003
707.963,42.000,0.168,240.004,0.003
716.758,43.000,0.172,242.985,0.003
725.590,44.000,0.174,245.979,0.003
734.780,45.000,0.177,249.095,0.003
748.299,46.000,0.182,253.678,0.004
754.010,47.000,0.185,255.614,0.004
763.262,48.000,0.188,258.750,0.004
773.414,49.000,0.191,262.192,0.004
784.614,50.000,0.195,265.989,0.004
792.225,51.000,0.198,268.569,0.004
799.861,52.000,0.201,271.158,0.004
813.936,53.000,0.205,275.929,0.004
821.189,54.000,0.208,278.388,0.004
829.207,55.000,0.211,281.106,0.004
837.718,56.000,0.214,283.991,0.004
850.325,57.000,0.219,288.265,0.004
856.443,58.000,0.222,290.339,0.004
864.930,59.000,0.224,293.216,0.004
875.958,60.000,0.228,296.955,0.004
886.961,61.000,0.232,300.685,0.005
894.115,62.000,0.235,303.110,0.005
900.061,63.000,0.237,305.126,0.005
914.000,64.000,0.241,309.851,0.005
921.006,65.000,0.245,312.227,0.005
928.605,66.000,0.248,314.803,0.005
937.301,67.000,0.251,317.751,0.005
949.970,68.000,0.255,322.045,0.005
956.902,69.000,0.258,324.396,0.005
965.253,70.000,0.261,327.227,0.005
975.467,71.000,0.264,330.689,0.005
986.926,72.000,0.268,334.574,0.005
991.947,73.000,0.271,336.276,0.005
1000.224,74.000,0.274,339.082,0.005
1013.670,75.000,0.278,343.640,0.005
1019.122,76.000,0.282,345.488,0.006
1026.412,77.000,0.285,347.960,0.006
1033.924,78.000,0.288,350.507,0.006
1046.408,79.000,0.292,354.738,0.006
1051.958,80.000,0.295,356.620,0.006
1058.249,81.000,0.298,358.753,0.006
1068.512,82.000,0.301,362.232,0.006
1077.789,83.000,0.305,365.377,0.006
1084.326,84.000,0.308,367.593,0.006
1091.210,85.000,0.311,369.927,0.006
1103.150,86.000,0.315,373.975,0.006
1110.527,87.000,0.318,376.475,0.006
1117.866,88.000,0.321,378.963,0.006
1126.686,89.000,0.324,381.953,0.006
1139.626,90.000,0.328,386.340,0.006
1144.301,91.000,0.331,387.925,0.007
1153.182,92.000,0.334,390.936,0.007
1163.815,93.000,0.338,394.540,0.007
1174.029,94.000,0.342,398.003,0.007
1180.690,95.000,0.345,400.261,0.007
1187.660,96.000,0.348,402.624,0.007
1201.019,97.000,0.352,407.153,0.007
1206.767,98.000,0.355,409.101,0.007
1215.846,99.000,0.358,412.179,0.007
1223.987,100.000,0.361,414.939,0.007
1235.200,101.000,0.365,418.740,0.007
1240.245,102.000,0.368,420.451,0.007
1246.635,103.000,0.371,422.617,0.007
1258.452,104.000,0.375,426.623,0.007
1266.643,105.000,0.378,429.400,0.007
1271.182,106.000,0.381,430.938,0.008
1278.978,107.000,0.384,433.581,0.008
1291.844,108.000,0.388,437.943,0.008
1297.284,109.000,0.391,439.787,0.008
1305.400,110.000,0.394,442.539,0.008
1313.863,111.000,0.397,445.407,0.008
1328.591,112.000,0.401,450.400,0.008
1335.264,113.000,0.404,452.663,0.008
1341.962,114.000,0.407,454.933,0.008
1356.099,115.000,0.411,459.726,0.008
1367.867,116.000,0.415,463.715,0.008
1375.441,117.000,0.418,466.283,0.008
1384.865,118.000,0.421,469.478,0.008
1400.506,119.000,0.425,474.780,0.008
1409.141,120.000,0.428,477.707,0.008
1417.479,121.000,0.431,480.534,0.008
1429.667,122.000,0.434,484.666,0.009
1445.283,123.000,0.438,489.960,0.009
1451.611,124.000,0.441,492.105,0.009
1460.184,125.000,0.444,495.011,0.009
1473.359,126.000,0.448,499.477,0.009
1484.016,127.000,0.452,503.090,0.009
1489.321,128.000,0.454,504.889,0.009
1498.794,129.000,0.457,508.100,0.009
1514.312,130.000,0.461,513.361,0.009
1521.960,131.000,0.464,515.954,0.009
1530.397,132.000,0.467,518.814,0.009
1540.241,133.000,0.471,522.151,0.009
1555.709,134.000,0.475,527.395,0.009
1561.088,135.000,0.478,529.218,0.009
1569.217,136.000,0.481,531.974,0.009
1584.253,137.000,0.484,537.071,0.010
1595.454,138.000,0.488,540.868,0.010
1602.867,139.000,0.491,543.382,0.010
1610.700,140.000,0.494,546.037,0.010
1627.748,141.000,0.498,551.816,0.010
1634.582,142.000,0.501,554.133,0.010
1643.093,143.000,0.504,557.018,0.010
1654.540,144.000,0.508,560.899,0.010
1670.033,145.000,0.512,566.151,0.010
1674.770,146.000,0.515,567.757,0.010
1683.257,147.000,0.517,570.634,0.010
1698.010,148.000,0.521,575.636,0.010
1708.643,149.000,0.525,579.240,0.010
1716.192,150.000,0.528,581.800,0.010
1724.852,151.000,0.531,584.735,0.010
1743.059,152.000,0.535,590.907,0.011
1751.619,153.000,0.538,593.810,0.011
1761.364,154.000,0.541,597.113,0.011
1774.267,155.000,0.544,601.487,0.011
1792.523,156.000,0.548,607.676,0.011
1801.047,157.000,0.551,610.566,0.011
1811.470,158.000,0.554,614.099,0.011
1830.060,159.000,0.558,620.401,0.011
1847.786,160.000,0.561,626.411,0.011
1859.998,161.000,0.564,630.550,0.011
1871.778,162.000,0.567,634.544,0.011
1894.574,163.000,0.571,642.272,0.011
1906.144,164.000,0.575,646.194,0.011
1916.642,165.000,0.578,649.753,0.011
1932.628,166.000,0.581,655.173,0.011
1950.959,167.000,0.585,661.387,0.012
1958.964,168.000,0.588,664.101,0.012
1970.448,169.000,0.591,667.994,0.012
1990.136,170.000,0.594,674.668,0.012
2003.236,171.000,0.598,679.109,0.012
2014.461,172.000,0.601,682.914,0.012
2024.305,173.000,0.604,686.251,0.012
2045.916,174.000,0.608,693.578,0.012
2054.946,175.000,0.611,696.639,0.012
2064.296,176.000,0.614,699.809,0.012
2079.049,177.000,0.617,704.810,0.012
2098.588,178.000,0.621,711.434,0.012
2106.273,179.000,0.624,714.039,0.012
2115.907,180.000,0.627,717.305,0.012
2136.457,181.000,0.631,724.272,0.012
2150.618,182.000,0.635,729.073,0.012
2159.981,183.000,0.638,732.247,0.013
2170.478,184.000,0.641,735.805,0.013
2192.978,185.000,0.645,743.433,0.013
2201.317,186.000,0.648,746.260,0.013
2211.358,187.000,0.651,749.664,0.013
2226.728,188.000,0.654,754.874,0.013
2243.245,189.000,0.658,760.473,0.013
2250.091,190.000,0.661,762.794,0.013
2259.527,191.000,0.664,765.993,0.013
2277.253,192.000,0.668,772.003,0.013
2289.588,193.000,0.671,776.184,0.013
2297.878,194.000,0.674,778.994,0.013
2306.809,195.000,0.677,782.022,0.013
2329.345,196.000,0.681,789.662,0.013
2335.414,197.000,0.684,791.720,0.013
2342.754,198.000,0.687,794.208,0.014
2357.754,199.000,0.690,799.293,0.014
2374.332,200.000,0.695,804.913,0.014
2380.401,201.000,0.697,806.970,0.014
2390.664,202.000,0.700,810.450,0.014
2407.268,203.000,0.704,816.078,0.014
2417.679,204.000,0.708,819.608,0.014
2424.932,205.000,0.711,822.067,0.014
2433.887,206.000,0.714,825.103,0.014
2450.898,207.000,0.718,830.869,0.014
2456.905,208.000,0.721,832.906,0.014
2465.244,209.000,0.724,835.733,0.014
2478.911,210.000,0.728,840.366,0.014
2492.246,211.000,0.732,844.886,0.014
2497.390,212.000,0.734,846.630,0.014
2504.951,213.000,0.737,849.194,0.015
2521.172,214.000,0.741,854.693,0.015
2528.598,215.000,0.745,857.210,0.015
2535.037,216.000,0.747,859.393,0.015
2543.746,217.000,0.750,862.345,0.015
2560.103,218.000,0.755,867.890,0.015
2564.420,219.000,0.758,869.354,0.015
2571.710,220.000,0.761,871.825,0.015
2584.033,221.000,0.764,876.003,0.015
2595.628,222.000,0.768,879.934,0.015
2600.045,223.000,0.771,881.431,0.015
2605.053,224.000,0.774,883.129,0.015
2619.978,225.000,0.778,888.189,0.015
2624.666,226.000,0.781,889.778,0.015
2630.118,227.000,0.784,891.626,0.015
2636.434,228.000,0.787,893.767,0.015
2648.128,229.000,0.791,897.731,0.016
2648.794,230.000,0.794,897.957,0.016
2653.136,231.000,0.797,899.429,0.016
2661.253,232.000,0.801,902.181,0.016
2666.211,233.000,0.805,903.862,0.016
2668.678,234.000,0.808,904.698,0.016
2674.106,235.000,0.810,906.538,0.016
2681.705,236.000,0.815,909.114,0.016
2682.543,237.000,0.818,909.398,0.016
2684.887,238.000,0.821,910.193,0.016
2688.711,239.000,0.824,911.489,0.016
2696.433,240.000,0.828,914.107,0.016
2695.594,241.000,0.831,913.823,0.016
2698.209,242.000,0.834,914.709,0.016
2705.327,243.000,0.837,917.122,0.016
2708.003,244.000,0.841,918.030,0.017
2708.300,245.000,0.844,918.130,0.017
2709.138,246.000,0.847,918.414,0.017
2716.318,247.000,0.851,920.848,0.017
2714.171,248.000,0.854,920.120,0.017
2717.169,249.000,0.857,921.137,0.017
2719.451,250.000,0.860,921.910,0.017
2725.495,251.000,0.865,923.959,0.017
2723.941,252.000,0.868,923.432,0.017
2725.618,253.000,0.871,924.001,0.017
2732.464,254.000,0.874,926.322,0.017
2729.837,255.000,0.878,925.431,0.017
2729.812,256.000,0.881,925.423,0.017
2731.490,257.000,0.884,925.992,0.017
2738.867,258.000,0.888,928.492,0.017
2736.621,259.000,0.891,927.731,0.018
2739.483,260.000,0.894,928.701,0.018
2742.851,261.000,0.897,929.843,0.018
2747.082,262.000,0.901,931.277,0.018
2742.567,263.000,0.904,929.747,0.018
2744.787,264.000,0.907,930.500,0.018
2750.215,265.000,0.911,932.339,0.018
2751.523,266.000,0.915,932.783,0.018
2750.906,267.000,0.917,932.574,0.018
2751.967,268.000,0.920,932.933,0.018
2757.049,269.000,0.924,934.656,0.018
2754.853,270.000,0.928,933.912,0.018
2757.703,271.000,0.931,934.878,0.018
2760.971,272.000,0.934,935.986,0.018
2762.439,273.000,0.938,936.484,0.018
2761.218,274.000,0.941,936.070,0.019
2761.897,275.000,0.944,936.300,0.019
2767.040,276.000,0.948,938.043,0.019
2765.906,277.000,0.951,937.659,0.019
2767.559,278.000,0.954,938.219,0.019
2768.533,279.000,0.957,938.549,0.019
2774.392,280.000,0.961,940.536,0.019
2769.976,281.000,0.964,939.039,0.019
2771.605,282.000,0.967,939.591,0.019
2774.466,283.000,0.970,940.561,0.019
2777.316,284.000,0.975,941.527,0.019
2775.182,285.000,0.977,940.803,0.019
2776.440,286.000,0.980,941.230,0.019
2781.991,287.000,0.984,943.112,0.019
2780.165,288.000,0.988,942.493,0.019
2780.597,289.000,0.991,942.639,0.020
2780.905,290.000,0.994,942.744,0.020
2786.900,291.000,0.998,944.776,0.020
2783.545,292.000,1.001,943.639,0.020
2785.223,293.000,1.004,944.207,0.020
2788.183,294.000,1.007,945.211,0.020
2789.984,295.000,1.011,945.821,0.020
2786.839,296.000,1.014,944.755,0.020
2787.295,297.000,1.017,944.910,0.020
2794.080,298.000,1.021,947.210,0.020
2790.922,299.000,1.025,946.139,0.020
2791.637,300.000,1.028,946.382,0.020
2794.351,301.000,1.030,947.302,0.020
2798.730,302.000,1.035,948.786,0.020
2793.093,303.000,1.038,946.875,0.020
2796.399,304.000,1.041,947.996,0.020
2799.408,305.000,1.044,949.016,0.021
2800.728,306.000,1.048,949.464,0.021
2798.027,307.000,1.051,948.548,0.021
2799.125,308.000,1.054,948.920,0.021
2805.897,309.000,1.057,951.216,0.021
2802.023,310.000,1.061,949.903,0.021
2802.566,311.000,1.064,950.087,0.021
2803.405,312.000,1.067,950.371,0.021
2808.759,313.000,1.071,952.186,0.021
2805.650,314.000,1.074,951.132,0.021
2806.748,315.000,1.077,951.504,0.021
2810.362,316.000,1.081,952.730,0.021
2811.941,317.000,1.085,953.265,0.021
2809.042,318.000,1.088,952.282,0.021
2809.523,319.000,1.091,952.445,0.021
2814.569,320.000,1.095,954.156,0.022
2812.632,321.000,1.098,953.499,0.022
2813.027,322.000,1.101,953.633,0.022
2814.359,323.000,1.104,954.085,0.022
2819.737,324.000,1.108,955.908,0.022
2815.395,325.000,1.111,954.436,0.022
2816.197,326.000,1.114,954.708,0.022
2820.132,327.000,1.117,956.042,0.022
2821.267,328.000,1.121,956.426,0.022
2818.281,329.000,1.124,955.414,0.022
2820.267,330.000,1.127,956.088,0.022
2826.472,331.000,1.131,958.191,0.022
2822.809,332.000,1.134,956.949,0.022
2823.166,333.000,1.137,957.070,0.022
2824.128,334.000,1.140,957.397,0.022
2828.927,335.000,1.144,959.023,0.023
2824.054,336.000,1.148,957.371,0.023
2825.313,337.000,1.151,957.798,0.023
2830.148,338.000,1.154,959.437,0.023
2829.235,339.000,1.158,959.128,0.023
2828.865,340.000,1.161,959.002,0.023
2829.359,341.000,1.164,959.170,0.023
2834.021,342.000,1.168,960.750,0.023
2831.678,343.000,1.171,959.956,0.023
2831.308,344.000,1.174,959.830,0.023
2832.072,345.000,1.177,960.090,0.023
2836.908,346.000,1.181,961.729,0.023
2832.146,347.000,1.184,960.115,0.023
2833.602,348.000,1.187,960.608,0.023
2837.648,349.000,1.190,961.980,0.023
2836.390,350.000,1.194,961.553,0.024
2835.403,351.000,1.197,961.219,0.024
2835.798,352.000,1.200,961.353,0.024
2841.817,353.000,1.204,963.393,0.024
2839.942,354.000,1.208,962.758,0.024
2838.980,355.000,1.211,962.431,0.024
2840.288,356.000,1.214,962.875,0.024
2845.284,357.000,1.218,964.568,0.024
2839.696,358.000,1.221,962.674,0.024
2843.026,359.000,1.224,963.803,0.024
2847.615,360.000,1.227,965.359,0.024
2845.148,361.000,1.231,964.522,0.024
2842.928,362.000,1.234,963.770,0.024
2842.385,363.000,1.237,963.586,0.024
2848.700,364.000,1.241,965.727,0.024
2844.802,365.000,1.244,964.405,0.024
2845.789,366.000,1.247,964.740,0.025
2848.602,367.000,1.250,965.693,0.025
2850.255,368.000,1.255,966.254,0.025
2846.184,369.000,1.258,964.874,0.025
2848.577,370.000,1.261,965.685,0.025
2852.746,371.000,1.264,967.098,0.025
2852.648,372.000,1.268,967.065,0.025
2850.822,373.000,1.271,966.446,0.025
2850.797,374.000,1.274,966.438,0.025
2856.447,375.000,1.277,968.353,0.025
2849.737,376.000,1.281,966.078,0.025
2850.144,377.000,1.284,966.216,0.025
2851.587,378.000,1.287,966.705,0.025
2856.200,379.000,1.291,968.269,0.025
2851.192,380.000,1.294,966.571,0.025
2851.895,381.000,1.297,966.810,0.026
2856.447,382.000,1.301,968.353,0.026
2855.337,383.000,1.305,967.976,0.026
2854.547,384.000,1.308,967.709,0.026
2854.103,385.000,1.311,967.558,0.026
2859.901,386.000,1.315,969.524,0.026
2855.830,387.000,1.318,968.144,0.026
2856.410,388.000,1.321,968.340,0.026
2858.396,389.000,1.324,969.014,0.026
2859.087,390.000,1.328,969.248,0.026
2856.373,391.000,1.331,968.328,0.026
2856.780,392.000,1.334,968.466,0.026
2862.220,393.000,1.337,970.310,0.026
2860.690,394.000,1.341,969.791,0.026
2859.013,395.000,1.344,969.223,0.026
2861.307,396.000,1.347,970.000,0.027
2866.636,397.000,1.351,971.807,0.027
2861.431,398.000,1.354,970.042,0.027
2862.442,399.000,1.357,970.385,0.027
2864.169,400.000,1.360,970.971,0.027
2866.513,401.000,1.364,971.765,0.027
2862.393,402.000,1.367,970.368,0.027
2863.256,403.000,1.370,970.661,0.027
2868.437,404.000,1.374,972.417,0.027
2863.811,405.000,1.378,970.849,0.027
2865.254,406.000,1.381,971.339,0.027
2865.489,407.000,1.384,971.418,0.027
2870.620,408.000,1.388,973.158,0.027
2866.389,409.000,1.391,971.723,0.027
2867.327,410.000,1.394,972.041,0.027
2870.041,411.000,1.397,972.961,0.028
2872.039,412.000,1.401,973.639,0.028
2868.166,413.000,1.404,972.325,0.028
2868.486,414.000,1.407,972.434,0.028
2873.075,415.000,1.411,973.990,0.028
2871.472,416.000,1.414,973.446,0.028
2870.164,417.000,1.417,973.003,0.028
2871.422,418.000,1.420,973.429,0.028
2875.209,419.000,1.424,974.713,0.028
2869.942,420.000,1.427,972.928,0.028
2872.458,421.000,1.430,973.781,0.028
2874.876,422.000,1.433,974.600,0.028
2876.455,423.000,1.438,975.136,0.028
2872.557,424.000,1.441,973.814,0.028
2874.481,425.000,1.444,974.467,0.028
2879.761,426.000,1.448,976.256,0.028
2873.618,427.000,1.451,974.174,0.029
2875.419,428.000,1.454,974.784,0.029
2874.975,429.000,1.457,974.634,0.029
2880.526,430.000,1.461,976.516,0.029
2874.284,431.000,1.464,974.400,0.029
2875.641,432.000,1.467,974.860,0.029
2879.415,433.000,1.470,976.139,0.029
2879.144,434.000,1.475,976.047,0.029
2875.542,435.000,1.477,974.826,0.029
2876.282,436.000,1.480,975.077,0.029
2881.019,437.000,1.484,976.683,0.029
2878.330,438.000,1.488,975.771,0.029
2875.419,439.000,1.491,974.784,0.029
2868.129,440.000,1.493,972.313,0.029
2867.055,441.000,1.498,971.949,0.029
2858.421,442.000,1.501,969.022,0.030
2856.817,443.000,1.504,968.478,0.030
2834.095,444.000,1.507,960.775,0.030
2755.297,445.000,1.511,934.062,0.030
-261.608,445.070,1.512,-88.687,0.030