File: Data/Tensile/Tensile_5.txt
""
"Test Method","March2014 Tensile - With Extensometer.msm"
"Sample I. D.","Tensile_5.mss"
"Specimen Number","2"

"Time (s)","Load (kN)","Extension (mm)","Stress (MPa)","Strain1 (mm)"

0.600,0.042,0.001,12.438,0.001
1.000,0.050,0.002,14.855,0.002
1.400,0.055,0.002,16.452,0.002
1.800,0.062,0.002,18.290,0.002
2.200,0.064,0.002,19.118,0.002
2.600,0.071,0.003,21.205,0.003
3.000,0.072,0.002,21.279,0.003
3.400,0.079,0.002,23.410,0.002
3.800,0.083,0.002,24.773,0.002
4.200,0.091,0.003,26.999,0.003
4.600,0.097,0.003,28.757,0.003
5.000,0.102,0.003,30.369,0.003
5.400,0.112,0.003,33.108,0.003
5.800,0.118,0.003,35.075,0.003
6.200,0.131,0.004,38.920,0.004
6.600,0.136,0.004,40.367,0.005
7.000,0.148,0.003,43.934,0.003
7.400,0.155,0.005,46.122,0.005
7.800,0.166,0.004,49.355,0.004
8.200,0.175,0.004,52.006,0.005
8.600,0.184,0.004,54.698,0.005
9.000,0.193,0.005,57.419,0.005
9.400,0.203,0.005,60.356,0.005
9.800,0.215,0.006,63.828,0.006
10.200,0.223,0.005,66.136,0.006
10.600,0.236,0.006,69.959,0.006
11.000,0.240,0.006,71.322,0.007
11.400,0.254,0.006,75.533,0.007
11.800,0.260,0.007,77.130,0.007
12.200,0.273,0.007,80.932,0.007
12.600,0.279,0.007,82.902,0.007
13.000,0.291,0.008,86.389,0.008
13.400,0.301,0.008,89.443,0.008
13.800,0.312,0.008,92.549,0.008
14.200,0.325,0.007,96.380,0.007
14.600,0.335,0.009,99.500,0.009
15.000,0.350,0.009,103.880,0.009
15.400,0.355,0.010,105.372,0.010
15.800,0.371,0.010,110.151,0.010
16.200,0.380,0.010,112.956,0.011
16.600,0.397,0.010,117.761,0.010
17.000,0.406,0.008,120.658,0.008
17.400,0.421,0.011,124.898,0.011
17.800,0.432,0.012,128.177,0.012
18.200,0.444,0.012,131.876,0.012
18.600,0.458,0.012,136.110,0.012
19.000,0.465,0.012,138.142,0.013
19.400,0.482,0.012,143.090,0.012
19.800,0.486,0.013,144.240,0.013
20.200,0.501,0.013,148.804,0.013
20.600,0.509,0.014,151.111,0.014
21.000,0.523,0.013,155.396,0.014
21.400,0.534,0.014,158.633,0.014
21.800,0.548,0.014,162.647,0.014
22.200,0.563,0.013,167.020,0.013
22.600,0.574,0.015,170.375,0.015
23.000,0.593,0.016,175.957,0.016
23.400,0.569,0.015,169.064,0.015
23.800,0.564,0.015,167.518,0.015
24.200,0.561,0.015,166.449,0.015
24.600,0.557,0.015,165.387,0.015
25.000,0.557,0.015,165.482,0.015
25.400,0.555,0.015,164.750,0.015
25.800,0.554,0.015,164.383,0.015
26.200,0.553,0.014,164.076,0.015
26.600,0.552,0.014,163.761,0.014
27.000,0.551,0.014,163.636,0.014
27.400,0.551,0.014,163.446,0.015
27.800,0.550,0.014,163.230,0.014
28.200,0.550,0.014,163.167,0.015
28.600,0.549,0.014,162.889,0.014
29.000,0.548,0.014,162.618,0.014
29.400,0.548,0.014,162.706,0.015
29.800,0.548,0.014,162.603,0.014
30.200,0.547,0.014,162.523,0.014
30.600,0.547,0.014,162.420,0.015
31.000,0.547,0.014,162.413,0.014
31.400,0.547,0.014,162.310,0.014
31.800,0.546,0.014,162.135,0.014
32.200,0.546,0.014,162.105,0.014
32.600,0.546,0.014,162.098,0.014
33.000,0.546,0.014,162.142,0.014
33.400,0.546,0.014,162.032,0.014
33.800,0.545,0.014,161.937,0.015
34.200,0.545,0.014,161.757,0.014
34.600,0.544,0.014,161.534,0.014
35.000,0.544,0.014,161.439,0.014
35.400,0.544,0.014,161.611,0.014
35.800,0.543,0.014,161.204,0.014
36.200,0.543,0.014,161.204,0.014
36.600,0.543,0.014,161.300,0.014
37.000,0.543,0.014,161.351,0.014
37.400,0.543,0.014,161.160,0.014
37.800,0.543,0.014,161.073,0.014
38.200,0.543,0.014,161.311,0.014
38.600,0.543,0.014,161.109,0.014
39.000,0.542,0.014,160.867,0.014
39.400,0.542,0.014,160.999,0.014
39.800,0.542,0.014,160.846,0.014
40.200,0.542,0.014,160.926,0.014
40.600,0.541,0.014,160.655,0.014
41.000,0.541,0.014,160.699,0.014
41.400,0.541,0.014,160.772,0.014
41.800,0.542,0.014,160.819,0.014
42.200,0.541,0.014,160.648,0.014
42.600,0.540,0.014,160.377,0.014
43.000,0.540,0.014,160.333,0.014
43.400,0.541,0.014,160.736,0.015
43.800,0.540,0.014,160.340,0.014
44.200,0.541,0.014,160.761,0.014
44.600,0.540,0.014,160.369,0.014
45.000,0.540,0.014,160.355,0.014
45.400,0.540,0.014,160.252,0.014
45.800,0.540,0.014,160.472,0.014
46.200,0.541,0.014,160.509,0.014
46.600,0.541,0.014,160.633,0.014
47.000,0.540,0.014,160.322,0.014
47.400,0.541,0.014,160.618,0.014
47.800,0.540,0.014,160.380,0.014
48.200,0.540,0.014,160.238,0.014
48.600,0.541,0.014,160.531,0.014
49.000,0.596,0.015,177.033,0.016
49.400,0.629,0.016,186.687,0.017
49.800,0.634,0.017,188.328,0.017
50.200,0.652,0.015,193.617,0.015
50.600,0.657,0.018,194.921,0.018
51.000,0.675,0.015,200.314,0.016
51.400,0.683,0.015,202.817,0.015
51.800,0.699,0.018,207.622,0.018
52.200,0.713,0.016,211.643,0.016
52.600,0.725,0.019,215.364,0.019
53.000,0.741,0.017,220.013,0.017
53.400,0.752,0.020,223.172,0.020
53.800,0.771,0.017,228.959,0.018
54.200,0.779,0.019,231.164,0.019
54.600,0.796,0.018,236.284,0.018
55.000,0.804,0.021,238.728,0.021
55.400,0.821,0.021,243.832,0.021
55.800,0.830,0.021,246.458,0.021
56.200,0.846,0.022,251.226,0.022
56.600,0.858,0.022,254.676,0.023
57.000,0.871,0.022,258.665,0.023
57.400,0.888,0.023,263.708,0.023
57.800,0.898,0.023,266.689,0.024
58.200,0.919,0.024,272.959,0.024
58.600,0.927,0.022,275.120,0.022
59.000,0.945,0.025,280.455,0.025
59.400,0.952,0.023,282.577,0.023
59.800,0.969,0.025,287.557,0.025
60.200,0.979,0.025,290.561,0.025
60.600,0.994,0.025,295.029,0.025
61.000,1.007,0.026,299.026,0.027
61.400,1.021,0.026,303.229,0.026
61.800,1.039,0.027,308.404,0.027
62.200,1.049,0.027,311.590,0.028
62.600,1.070,0.027,317.582,0.028
63.000,1.078,0.028,319.928,0.028
63.400,1.099,0.028,326.416,0.029
63.800,1.105,0.029,328.027,0.029
64.200,1.124,0.028,333.616,0.029
64.600,1.134,0.029,336.696,0.029
65.000,1.152,0.030,342.174,0.030
65.400,1.169,0.030,347.002,0.030
65.800,1.147,0.029,340.516,0.030
66.200,1.138,0.029,337.740,0.029
66.600,1.132,0.029,336.018,0.029
67.000,1.128,0.029,334.832,0.029
67.400,1.125,0.029,334.136,0.029
67.800,1.123,0.029,333.297,0.029
68.200,1.121,0.029,332.957,0.029
68.600,1.120,0.029,332.510,0.029
69.000,1.118,0.029,331.993,0.029
69.400,1.118,0.029,331.814,0.029
69.800,1.117,0.029,331.543,0.029
70.200,1.115,0.029,331.067,0.029
70.600,1.114,0.029,330.876,0.029
71.000,1.114,0.028,330.723,0.029
71.400,1.113,0.029,330.587,0.029
71.800,1.112,0.029,330.159,0.029
72.200,1.113,0.029,330.349,0.029
72.600,1.111,0.029,329.778,0.029
73.000,1.111,0.029,329.756,0.029
73.400,1.110,0.029,329.463,0.029
73.800,1.110,0.029,329.510,0.029
74.200,1.110,0.029,329.485,0.029
74.600,1.109,0.028,329.155,0.029
75.000,1.108,0.029,328.836,0.029
75.400,1.108,0.029,328.987,0.029
75.800,1.108,0.029,328.822,0.029
76.200,1.108,0.028,328.935,0.029
76.600,1.108,0.029,328.895,0.029
77.000,1.108,0.029,328.906,0.029
77.400,1.107,0.029,328.657,0.029
77.800,1.106,0.028,328.485,0.028
78.200,1.106,0.028,328.386,0.029
78.600,1.108,0.028,328.921,0.028
79.000,1.105,0.028,328.093,0.029
79.400,1.106,0.028,328.342,0.029
79.800,1.107,0.028,328.532,0.029
80.200,1.106,0.028,328.401,0.029
80.600,1.105,0.028,328.042,0.029
81.000,1.105,0.029,328.020,0.029
81.400,1.104,0.028,327.719,0.029
81.800,1.104,0.029,327.888,0.029
82.200,1.104,0.028,327.690,0.029
82.600,1.104,0.029,327.789,0.029
83.000,1.104,0.028,327.683,0.029
83.400,1.103,0.028,327.514,0.029
83.800,1.103,0.028,327.474,0.029
84.200,1.166,0.030,346.119,0.030
84.600,1.217,0.031,361.238,0.031
85.000,1.236,0.032,366.878,0.032
85.400,1.259,0.032,373.690,0.032
85.800,1.270,0.033,376.927,0.033
86.200,1.297,0.033,385.150,0.033
86.600,1.307,0.034,387.933,0.034
87.000,1.334,0.034,396.104,0.034
87.400,1.345,0.035,399.334,0.035
87.800,1.371,0.035,407.098,0.035
88.200,1.389,0.036,412.321,0.036
88.600,1.410,0.037,418.730,0.037
89.000,1.433,0.037,425.454,0.037
89.400,1.453,0.038,431.300,0.038
89.800,1.481,0.038,439.785,0.039
90.200,1.494,0.037,443.488,0.037
90.600,1.524,0.039,452.472,0.040
91.000,1.536,0.038,456.192,0.038
91.400,1.565,0.038,464.605,0.038
91.800,1.578,0.040,468.502,0.040
92.200,1.606,0.041,476.765,0.041
92.600,1.624,0.041,482.266,0.042
93.000,1.649,0.042,489.708,0.042
93.400,1.672,0.041,496.355,0.041
93.800,1.691,0.043,502.189,0.044
94.200,1.719,0.044,510.327,0.044
94.600,1.733,0.045,514.480,0.045
95.000,1.763,0.046,523.416,0.046
95.400,1.760,0.046,522.486,0.046
95.800,1.741,0.045,516.853,0.045
96.200,1.732,0.045,514.121,0.045
96.600,1.725,0.045,512.107,0.045
97.000,1.721,0.045,511.030,0.045
97.400,1.718,0.045,510.027,0.045
97.800,1.716,0.044,509.587,0.045
98.200,1.713,0.044,508.540,0.044
98.600,1.712,0.044,508.261,0.045
99.000,1.711,0.044,507.862,0.045
99.400,1.709,0.044,507.272,0.044
99.800,1.708,0.044,507.031,0.045
100.200,1.706,0.044,506.599,0.044
100.600,1.706,0.044,506.379,0.044
101.000,1.705,0.044,506.320,0.045
101.400,1.703,0.044,505.764,0.045
101.800,1.705,0.044,506.159,0.044
102.200,1.717,0.044,509.763,0.044
102.600,1.796,0.046,533.092,0.046
103.000,1.830,0.047,543.296,0.047
103.400,1.855,0.048,550.731,0.048
103.800,1.870,0.048,555.184,0.049
104.200,1.891,0.049,561.513,0.049
104.600,1.916,0.049,568.874,0.049
105.000,1.934,0.050,574.111,0.050
105.400,1.962,0.050,582.656,0.050
105.800,1.977,0.051,586.849,0.051
106.200,2.008,0.052,596.166,0.052
106.600,2.018,0.052,599.265,0.052
107.000,2.047,0.053,607.835,0.053
107.400,2.062,0.053,612.175,0.053
107.800,2.088,0.054,619.965,0.054
108.200,2.108,0.054,625.905,0.055
108.600,2.129,0.055,632.051,0.055
109.000,2.156,0.056,640.240,0.056
109.400,2.173,0.056,645.155,0.056
109.800,2.204,0.057,654.340,0.057
110.200,2.214,0.058,657.446,0.058
110.600,2.246,0.059,666.726,0.059
111.000,2.256,0.059,669.945,0.059
111.400,2.285,0.060,678.314,0.060
111.800,2.298,0.060,682.379,0.060
112.200,2.284,0.061,678.182,0.061
112.600,2.270,0.060,673.850,0.060
113.000,2.260,0.060,670.945,0.060
113.400,2.253,0.059,668.931,0.060
113.800,2.250,0.060,667.986,0.060
114.200,2.246,0.059,666.763,0.060
114.600,2.242,0.059,665.796,0.059
115.000,2.241,0.059,665.327,0.059
115.400,2.237,0.059,664.199,0.059
115.800,2.237,0.059,664.272,0.059
116.200,2.236,0.059,663.859,0.059
116.600,2.234,0.059,663.284,0.059
117.000,2.233,0.059,662.998,0.059
117.400,2.232,0.059,662.558,0.059
117.800,2.231,0.059,662.247,0.059
118.200,2.229,0.059,661.863,0.059
118.600,2.230,0.059,661.958,0.059
119.000,2.283,0.060,677.941,0.060
119.400,2.340,0.062,694.806,0.062
119.800,2.377,0.063,705.665,0.063
120.200,2.399,0.064,712.235,0.064
120.600,2.412,0.065,715.993,0.065
121.000,2.435,0.066,722.973,0.066
121.400,2.444,0.066,725.676,0.067
121.800,2.468,0.067,732.886,0.067
122.200,2.478,0.068,735.638,0.068
122.600,2.497,0.068,741.388,0.069
123.000,2.507,0.069,744.369,0.070
123.400,2.522,0.071,748.936,0.071
123.800,2.535,0.073,752.683,0.073
124.200,2.546,0.074,756.008,0.075
124.600,2.562,0.076,760.616,0.076
125.000,2.569,0.075,762.670,0.075
125.400,2.544,0.075,755.331,0.075
125.800,2.532,0.075,751.635,0.075
126.200,2.525,0.075,749.628,0.075
126.600,2.519,0.075,747.955,0.075
127.000,2.516,0.074,746.911,0.074
127.400,2.511,0.074,745.541,0.074
127.800,2.509,0.074,744.845,0.074
128.200,2.507,0.074,744.355,0.074
128.600,2.504,0.074,743.432,0.074
129.000,2.503,0.074,743.175,0.074
129.400,2.500,0.074,742.355,0.074
129.800,2.499,0.074,742.055,0.074
130.200,2.498,0.074,741.791,0.074
130.600,2.497,0.074,741.300,0.074
131.000,2.496,0.074,741.212,0.074
131.400,2.495,0.074,740.758,0.074
131.800,2.494,0.074,740.458,0.074
132.200,2.494,0.074,740.469,0.074
132.600,2.493,0.074,740.040,0.074
133.000,2.491,0.074,739.674,0.074
133.400,2.489,0.074,739.139,0.074
133.800,2.552,0.077,757.686,0.077
134.200,2.586,0.080,767.809,0.080
134.600,2.602,0.082,772.584,0.082
135.000,2.606,0.083,773.749,0.083
135.400,2.618,0.085,777.389,0.085
135.800,2.625,0.086,779.235,0.086
136.200,2.633,0.088,781.872,0.089
136.600,2.640,0.090,783.689,0.090
137.000,2.646,0.092,785.579,0.092
137.400,2.658,0.094,789.029,0.094
137.800,2.633,0.094,781.653,0.094
138.200,2.622,0.094,778.375,0.094
138.600,2.614,0.094,776.243,0.094
139.000,2.610,0.094,774.958,0.094
139.400,2.605,0.094,773.346,0.094
139.800,2.602,0.094,772.562,0.094
140.200,2.599,0.094,771.683,0.094
140.600,2.597,0.093,770.966,0.093
141.000,2.594,0.094,770.233,0.094
141.400,2.592,0.093,769.512,0.094
141.800,2.591,0.093,769.193,0.094
142.200,2.590,0.093,769.025,0.094
142.600,2.588,0.093,768.475,0.093
143.000,2.591,0.093,769.361,0.093
143.400,2.659,0.095,789.366,0.095
143.800,2.672,0.097,793.248,0.097
144.200,2.672,0.099,793.467,0.099
144.600,2.681,0.102,796.009,0.102
145.000,2.685,0.103,797.229,0.103
145.400,2.690,0.105,798.631,0.105
145.800,2.698,0.106,801.056,0.106
146.200,2.680,0.108,795.650,0.108
146.600,2.668,0.108,791.995,0.108
147.000,2.662,0.107,790.296,0.107
147.400,2.657,0.107,788.758,0.107
147.800,2.654,0.107,787.864,0.108
148.200,2.651,0.107,787.073,0.108
148.600,2.647,0.107,785.820,0.108
149.000,2.645,0.107,785.264,0.108
149.400,2.644,0.107,784.985,0.107
149.800,2.642,0.107,784.528,0.107
150.200,2.640,0.107,783.806,0.107
150.600,2.638,0.107,783.297,0.107
151.000,2.637,0.107,782.846,0.107
151.400,2.636,0.107,782.737,0.107
151.800,2.635,0.107,782.308,0.107
152.200,2.634,0.107,782.063,0.107
152.600,2.673,0.108,793.533,0.108
153.000,2.713,0.110,805.400,0.110
153.400,2.712,0.112,805.070,0.112
153.800,2.721,0.115,807.949,0.115
154.200,2.721,0.116,807.883,0.116
154.600,2.730,0.118,810.593,0.118
155.000,2.729,0.121,810.322,0.121
155.400,2.736,0.123,812.311,0.123
155.800,2.737,0.125,812.644,0.125
156.200,2.742,0.126,814.028,0.126
156.600,2.746,0.128,815.332,0.128
157.000,2.747,0.130,815.691,0.130
157.400,2.755,0.132,818.013,0.132
157.800,2.756,0.134,818.255,0.134
158.200,2.766,0.136,821.214,0.136
158.600,2.764,0.138,820.613,0.139
159.000,2.771,0.140,822.803,0.141
159.400,2.770,0.142,822.466,0.142
159.800,2.775,0.145,823.785,0.145
160.200,2.777,0.146,824.503,0.146
160.600,2.779,0.148,824.957,0.148
161.000,2.785,0.147,826.759,0.147
161.400,2.786,0.152,827.030,0.152
161.800,2.792,0.154,828.920,0.154
162.200,2.765,0.153,821.067,0.154
162.600,2.755,0.153,818.071,0.154
163.000,2.750,0.153,816.412,0.153
163.400,2.747,0.153,815.632,0.153
163.800,2.743,0.153,814.534,0.153
164.200,2.741,0.153,813.816,0.153
164.600,2.739,0.153,813.211,0.153
165.000,2.736,0.153,812.292,0.153
165.400,2.736,0.153,812.241,0.153
165.800,2.733,0.153,811.574,0.153
166.200,2.733,0.153,811.311,0.153
166.600,2.730,0.153,810.637,0.153
167.000,2.729,0.153,810.315,0.153
167.400,2.729,0.153,810.128,0.153
167.800,2.727,0.153,809.787,0.153
168.200,2.727,0.153,809.655,0.153
168.600,2.725,0.153,809.003,0.153
169.000,2.725,0.152,808.945,0.153
169.400,2.770,0.154,822.543,0.154
169.800,2.801,0.156,831.556,0.157
170.200,2.799,0.156,831.000,0.156
170.600,2.806,0.160,833.021,0.160
171.000,2.804,0.162,832.655,0.162
171.400,2.813,0.164,835.120,0.165
171.800,2.809,0.167,834.135,0.167
172.200,2.817,0.168,836.464,0.168
172.600,2.815,0.170,835.662,0.170
173.000,2.819,0.171,837.039,0.171
173.400,2.819,0.174,837.057,0.174
173.800,2.823,0.176,838.083,0.177
174.200,2.827,0.179,839.211,0.179
174.600,2.828,0.181,839.504,0.181
175.000,2.834,0.183,841.489,0.183
175.400,2.811,0.184,834.669,0.184
175.800,2.798,0.183,830.729,0.184
176.200,2.794,0.183,829.425,0.183
176.600,2.790,0.183,828.312,0.183
177.000,2.786,0.183,827.132,0.183
177.400,2.784,0.183,826.539,0.183
177.800,2.782,0.183,825.843,0.183
178.200,2.780,0.183,825.374,0.183
178.600,2.778,0.183,824.781,0.183
179.000,2.777,0.183,824.440,0.183
179.400,2.775,0.183,824.005,0.183
179.800,2.774,0.183,823.653,0.183
180.200,2.772,0.183,823.159,0.183
180.600,2.772,0.183,823.060,0.183
181.000,2.769,0.183,822.269,0.183
181.400,2.770,0.183,822.276,0.183
181.800,2.769,0.183,822.188,0.183
182.200,2.768,0.183,821.888,0.183
182.600,2.767,0.183,821.529,0.183
183.000,2.766,0.183,821.353,0.183
183.400,2.765,0.183,820.892,0.183
183.800,2.765,0.183,820.932,0.183
184.200,2.764,0.183,820.738,0.183
184.600,2.764,0.183,820.518,0.183
185.000,2.763,0.183,820.481,0.183
185.400,2.763,0.183,820.221,0.183
185.800,2.763,0.183,820.210,0.183
186.200,2.762,0.183,820.020,0.183
186.600,2.762,0.183,820.013,0.183
187.000,2.761,0.183,819.829,0.183
187.400,2.787,0.184,827.389,0.184
187.800,2.844,0.186,844.426,0.186
188.200,2.839,0.187,842.998,0.187
188.600,2.845,0.188,844.774,0.188
189.000,2.842,0.192,843.760,0.192
189.400,2.849,0.195,845.833,0.195
189.800,2.847,0.196,845.203,0.196
190.200,2.853,0.197,846.939,0.197
190.600,2.850,0.201,846.096,0.201
191.000,2.853,0.201,847.041,0.201
191.400,2.855,0.205,847.708,0.205
191.800,2.856,0.208,848.063,0.208
192.200,2.863,0.210,850.008,0.210
192.600,2.843,0.209,844.016,0.209
193.000,2.830,0.209,840.288,0.209
193.400,2.824,0.209,838.453,0.209
193.800,2.820,0.209,837.241,0.209
194.200,2.817,0.208,836.369,0.209
194.600,2.815,0.209,835.746,0.209
195.000,2.813,0.209,835.263,0.209
195.400,2.811,0.209,834.450,0.209
195.800,2.809,0.211,833.959,0.211
196.200,2.807,0.211,833.410,0.211
196.600,2.806,0.210,833.245,0.211
197.000,2.804,0.211,832.633,0.211
197.400,2.805,0.211,832.699,0.211
197.800,2.802,0.211,831.956,0.211
198.200,2.801,0.211,831.703,0.211
198.600,2.801,0.211,831.710,0.211
199.000,2.801,0.210,831.491,0.211
199.400,2.800,0.211,831.227,0.211
199.800,2.798,0.210,830.802,0.211
200.200,2.798,0.210,830.623,0.211
200.600,2.797,0.210,830.436,0.211
201.000,2.796,0.210,830.231,0.211
201.400,2.852,0.212,846.631,0.212
201.800,2.869,0.214,851.883,0.214
202.200,2.867,0.213,851.205,0.214
202.600,2.867,0.219,851.209,0.219
203.000,2.871,0.219,852.326,0.219
203.400,2.871,0.224,852.355,0.224
203.800,2.878,0.226,854.388,0.226
204.200,2.875,0.228,853.652,0.228
204.600,2.882,0.231,855.780,0.231
205.000,2.878,0.233,854.425,0.233
205.400,2.883,0.235,855.937,0.235
205.800,2.880,0.237,855.091,0.237
206.200,2.884,0.239,856.139,0.239
206.600,2.886,0.239,856.794,0.239
207.000,2.883,0.244,855.900,0.244
207.400,2.860,0.244,849.224,0.244
207.800,2.852,0.244,846.807,0.244
208.200,2.848,0.244,845.579,0.244
208.600,2.844,0.244,844.466,0.244
209.000,2.841,0.244,843.467,0.244
209.400,2.838,0.244,842.752,0.244
209.800,2.837,0.243,842.456,0.244
210.200,2.836,0.243,842.038,0.244
210.600,2.834,0.243,841.547,0.244
211.000,2.834,0.243,841.533,0.244
211.400,2.831,0.243,840.628,0.244
211.800,2.832,0.243,840.705,0.243
212.200,2.830,0.243,840.126,0.243
212.600,2.829,0.243,840.053,0.244
213.000,2.881,0.245,855.358,0.245
213.400,2.896,0.248,859.860,0.248
213.800,2.898,0.250,860.292,0.250
214.200,2.895,0.253,859.427,0.253
214.600,2.903,0.255,861.910,0.255
215.000,2.898,0.256,860.559,0.256
215.400,2.904,0.260,862.130,0.261
215.800,2.900,0.262,860.936,0.263
216.200,2.905,0.263,862.540,0.263
216.600,2.902,0.264,861.698,0.264
217.000,2.905,0.270,862.500,0.270
217.400,2.907,0.271,862.973,0.271
217.800,2.902,0.274,861.566,0.275
218.200,2.880,0.275,855.018,0.275
218.600,2.873,0.275,852.883,0.275
219.000,2.868,0.275,851.524,0.275
219.400,2.864,0.275,850.216,0.275
219.800,2.861,0.275,849.363,0.275
220.200,2.859,0.274,848.740,0.275
220.600,2.856,0.274,848.052,0.275
221.000,2.856,0.274,848.078,0.274
221.400,2.855,0.274,847.627,0.274
221.800,2.853,0.274,846.950,0.274
222.200,2.851,0.274,846.536,0.274
222.600,2.850,0.274,846.257,0.274
223.000,2.850,0.274,846.166,0.274
223.400,2.848,0.274,845.697,0.274
223.800,2.848,0.274,845.686,0.274
224.200,2.846,0.274,844.939,0.274
224.600,2.874,0.275,853.370,0.276
225.000,2.923,0.277,867.851,0.277
225.400,2.914,0.279,865.148,0.279
225.800,2.913,0.281,864.943,0.281
226.200,2.908,0.283,863.478,0.283
226.600,2.908,0.283,863.353,0.283
227.000,2.912,0.284,864.518,0.284
227.400,2.910,0.286,863.969,0.286
227.800,2.913,0.288,864.892,0.288
228.200,2.897,0.286,860.182,0.287
228.600,2.864,0.285,850.260,0.285
229.000,1.792,0.214,531.986,0.214
229.400,1.784,0.207,529.529,0.207
229.800,1.752,0.206,520.215,0.206
230.200,1.746,0.206,518.384,0.206
230.600,1.742,0.206,517.132,0.206
231.000,1.727,0.205,512.825,0.205
231.400,1.715,0.204,509.060,0.204
231.800,1.705,0.203,506.328,0.204
232.200,1.701,0.203,505.009,0.204
232.600,1.698,0.203,504.141,0.203
233.000,1.695,0.203,503.258,0.203
233.400,1.691,0.203,502.204,0.203
233.800,1.689,0.203,501.431,0.203
234.200,1.686,0.203,500.643,0.203
234.600,1.684,0.202,499.845,0.203
235.000,1.682,0.202,499.325,0.202
235.400,1.679,0.202,498.387,0.202
235.800,1.674,0.202,497.150,0.202
236.200,1.670,0.202,495.970,0.202
236.600,1.667,0.201,494.901,0.202
237.000,1.661,0.201,493.015,0.201
237.400,1.648,0.200,489.356,0.201
237.800,1.629,0.199,483.606,0.200
238.200,1.621,0.199,481.365,0.199
238.600,1.609,0.198,477.636,0.198
239.000,1.593,0.197,472.989,0.198
239.400,1.584,0.197,470.333,0.197
239.800,1.577,0.196,468.074,0.196
240.200,1.564,0.196,464.254,0.196
240.600,1.557,0.195,462.163,0.196
241.000,1.553,0.195,461.031,0.195
241.400,1.550,0.195,460.137,0.195
241.800,1.546,0.195,459.090,0.195
242.200,1.544,0.195,458.277,0.195
242.600,1.541,0.195,457.555,0.195
243.000,1.539,0.195,457.039,0.195
243.400,1.536,0.195,456.160,0.195
243.800,1.534,0.195,455.567,0.195
244.200,1.533,0.195,455.164,0.195
244.600,1.532,0.194,454.849,0.195
245.000,1.531,0.194,454.600,0.194
245.400,1.530,0.194,454.233,0.194
245.800,1.530,0.194,454.197,0.194
246.200,1.529,0.194,454.039,0.194
246.600,1.529,0.194,453.909,0.194
247.000,1.528,0.194,453.684,0.194
247.400,1.527,0.194,453.479,0.194
247.800,1.527,0.194,453.479,0.194
248.200,1.529,0.194,453.882,0.194
248.600,1.526,0.194,453.201,0.194
249.000,1.526,0.194,453.018,0.194
249.400,1.526,0.194,452.933,0.194
249.800,1.526,0.194,452.966,0.194
250.200,1.526,0.194,453.164,0.194
250.600,1.525,0.194,452.703,0.194
251.000,1.525,0.194,452.758,0.194
251.400,1.525,0.194,452.710,0.194
251.800,1.524,0.194,452.410,0.194
252.200,1.525,0.194,452.688,0.194
252.600,1.523,0.194,452.226,0.194
253.000,1.523,0.194,452.270,0.194
253.400,1.522,0.194,452.029,0.194
253.800,1.523,0.194,452.194,0.194
254.200,1.522,0.194,451.933,0.194
254.600,1.522,0.194,451.941,0.194
255.000,1.523,0.194,452.051,0.194
255.400,1.523,0.194,452.153,0.194
255.800,1.522,0.194,451.816,0.194
256.200,1.523,0.194,452.109,0.194
256.600,1.520,0.194,451.238,0.194
257.000,1.523,0.194,452.080,0.194
257.400,1.522,0.194,451.860,0.194
257.800,1.521,0.194,451.648,0.194
258.200,1.522,0.194,451.776,0.194
258.600,1.522,0.194,451.849,0.194
259.000,1.522,0.194,451.890,0.194
259.400,1.521,0.193,451.651,0.194
259.800,1.521,0.194,451.531,0.194
260.200,1.521,0.193,451.443,0.194
260.600,1.521,0.193,451.560,0.194
261.000,1.521,0.193,451.553,0.194
261.400,1.520,0.193,451.406,0.194
261.800,1.520,0.194,451.432,0.194
262.200,1.521,0.193,451.633,0.194
262.600,1.521,0.193,451.516,0.194
263.000,1.521,0.193,451.560,0.194
263.400,1.520,0.194,451.311,0.194
263.800,1.520,0.194,451.157,0.194
264.200,1.520,0.193,451.272,0.194
264.600,1.520,0.193,451.201,0.193
265.000,1.519,0.193,451.142,0.194
265.400,1.520,0.193,451.208,0.194
265.800,1.519,0.194,451.091,0.194
266.200,1.518,0.193,450.688,0.194
266.600,1.519,0.194,450.864,0.194
267.000,1.518,0.193,450.575,0.194
267.400,1.519,0.193,450.886,0.194
267.800,1.519,0.193,450.908,0.193
268.200,1.518,0.193,450.780,0.194
268.600,1.519,0.193,450.930,0.194
269.000,1.517,0.193,450.527,0.194
269.400,1.518,0.193,450.626,0.194
269.800,1.547,0.194,459.214,0.194
270.200,1.542,0.193,457.973,0.193
270.600,1.476,0.190,438.115,0.190
271.000,1.414,0.187,419.785,0.187
271.400,1.232,0.180,365.673,0.181
271.800,1.068,0.173,317.010,0.174
272.200,0.951,0.171,282.349,0.171
272.300,-0.303,-0.004,-90.000,-0.004